Workbook

Sheet How to use
A1: Glamour vendor review
A3: Each vendor has a tab. Set Keep (yellow column) to N for any glamour you want off that vendor.
A4: Rows shaded red were pre-set to N by a first pass (reason in the Flag column); set them back to Y to keep.
A5: First-pass rules (weapon tabs only): test/joke/non-gear names, low-tier words (Rusty, Cracked...), lower Defiant tiers, Small/Large when a Medium/plain version exists.
A6: Armor tabs: one row per texture and color (the same 8 colors on every slot), listed helm to boots. The name is just one item with that look.
A7: Patterns tab: name rules that drop matches on every vendor (e.g. "Practice" drops anything with Practice).
A8: Summary tab: how many each vendor keeps. Lists must stay at 500 or fewer.
A10: When done: save this file and say so. The vendor lists are rebuilt from it; NPCs, prices and spots stay.
A11: Example: on 1H Slashing, set "Rusty Short Sword" to N to remove it.

Sheet Summary
A1: Vendor | B1: Looks | C1: Kept | D1: Dropped | E1: Pattern drops not included
A2: Plate | B2: =COUNTA('Plate'!A:A)-1 | C2: =COUNTIF('Plate'!E:E,"Y") | D2: =COUNTIF('Plate'!E:E,"N") | E2: Patterns are applied when the lists are rebuilt
A3: Chain | B3: =COUNTA('Chain'!A:A)-1 | C3: =COUNTIF('Chain'!E:E,"Y") | D3: =COUNTIF('Chain'!E:E,"N")
A4: Leather | B4: =COUNTA('Leather'!A:A)-1 | C4: =COUNTIF('Leather'!E:E,"Y") | D4: =COUNTIF('Leather'!E:E,"N")
A5: Exotic Helms | B5: =COUNTA('Exotic Helms'!A:A)-1 | C5: =COUNTIF('Exotic Helms'!E:E,"Y") | D5: =COUNTIF('Exotic Helms'!E:E,"N")
A6: Exotic Chests | B6: =COUNTA('Exotic Chests'!A:A)-1 | C6: =COUNTIF('Exotic Chests'!E:E,"Y") | D6: =COUNTIF('Exotic Chests'!E:E,"N")
A7: Exotic Sleeves | B7: =COUNTA('Exotic Sleeves'!A:A)-1 | C7: =COUNTIF('Exotic Sleeves'!E:E,"Y") | D7: =COUNTIF('Exotic Sleeves'!E:E,"N")
A8: Exotic Bracers | B8: =COUNTA('Exotic Bracers'!A:A)-1 | C8: =COUNTIF('Exotic Bracers'!E:E,"Y") | D8: =COUNTIF('Exotic Bracers'!E:E,"N")
A9: Exotic Gloves | B9: =COUNTA('Exotic Gloves'!A:A)-1 | C9: =COUNTIF('Exotic Gloves'!E:E,"Y") | D9: =COUNTIF('Exotic Gloves'!E:E,"N")
A10: Exotic Leggings | B10: =COUNTA('Exotic Leggings'!A:A)-1 | C10: =COUNTIF('Exotic Leggings'!E:E,"Y") | D10: =COUNTIF('Exotic Leggings'!E:E,"N")
A11: Exotic Boots | B11: =COUNTA('Exotic Boots'!A:A)-1 | C11: =COUNTIF('Exotic Boots'!E:E,"Y") | D11: =COUNTIF('Exotic Boots'!E:E,"N")
A12: Robes | B12: =COUNTA('Robes'!A:A)-1 | C12: =COUNTIF('Robes'!E:E,"Y") | D12: =COUNTIF('Robes'!E:E,"N")
A13: 1H Slashing | B13: =COUNTA('1H Slashing'!A:A)-1 | C13: =COUNTIF('1H Slashing'!E:E,"Y") | D13: =COUNTIF('1H Slashing'!E:E,"N")
A14: 1H Blunt | B14: =COUNTA('1H Blunt'!A:A)-1 | C14: =COUNTIF('1H Blunt'!E:E,"Y") | D14: =COUNTIF('1H Blunt'!E:E,"N")
A15: 1H Piercing | B15: =COUNTA('1H Piercing'!A:A)-1 | C15: =COUNTIF('1H Piercing'!E:E,"Y") | D15: =COUNTIF('1H Piercing'!E:E,"N")
A16: Two-Handed | B16: =COUNTA('Two-Handed'!A:A)-1 | C16: =COUNTIF('Two-Handed'!E:E,"Y") | D16: =COUNTIF('Two-Handed'!E:E,"N")
A17: Shields | B17: =COUNTA('Shields'!A:A)-1 | C17: =COUNTIF('Shields'!E:E,"Y") | D17: =COUNTIF('Shields'!E:E,"N")
A18: Fist & Ranged | B18: =COUNTA('Fist & Ranged'!A:A)-1 | C18: =COUNTIF('Fist & Ranged'!E:E,"Y") | D18: =COUNTIF('Fist & Ranged'!E:E,"N")
A19: Unusual Weapons | B19: =COUNTA('Unusual Weapons'!A:A)-1 | C19: =COUNTIF('Unusual Weapons'!E:E,"Y") | D19: =COUNTIF('Unusual Weapons'!E:E,"N")
A20: Total | B20: =SUM(B2:B19) | C20: =SUM(C2:C19) | D20: =SUM(D2:D19)

Sheet Patterns
A1: Drop names containing | B1: Applies to (vendor, or blank = all) | C1: Note
A2: Practice | C2: Example rule: edit or delete

Sheet Plate
A1: Item ID | B1: Glamour | C1: Look of | D1: Flag | E1: Keep
A2: 910262 | B2: Glamour - 'Helm of Brute Strength' | C2: Helm of Brute Strength | E2: Y
A3: 913770 | B3: Glamour - 'Blackened Darkscale Helm' | C3: Blackened Darkscale Helm | E3: Y
A4: 920658 | B4: Glamour - 'Platinum Efreeti Helm' | C4: Platinum Efreeti Helm | E4: Y
A5: 913225 | B5: Glamour - 'Red Fine Plate Helm' | C5: Red Fine Plate Helm | E5: Y
A6: 916508 | B6: Glamour - 'Prismatic Scaled Helm' | C6: Prismatic Scaled Helm | E6: Y
A7: 927283 | B7: Glamour - 'Flawed Consigned Plate Helm' | C7: Flawed Consigned Plate Helm | E7: Y
A8: 914731 | B8: Glamour - 'Helm of the Axebringer' | C8: Helm of the Axebringer | E8: Y
A9: 916466 | B9: Glamour - 'Helm of the Harmonious Soul' | C9: Helm of the Harmonious Soul | E9: Y
A10: 910641 | B10: Glamour - 'Field Breastplate' | C10: Field Breastplate | E10: Y
A11: 913773 | B11: Glamour - 'Blackened Darkscale Breastplate' | C11: Blackened Darkscale Breastplate | E11: Y
A12: 920659 | B12: Glamour - 'Platinum Efreeti Chestplate' | C12: Platinum Efreeti Chestplate | E12: Y
A13: 913226 | B13: Glamour - 'Red Fine Plate Breastplate' | C13: Red Fine Plate Breastplate | E13: Y
... A57: 916582 | B57: Glamour - 'Boots of Superior Divinity' | C57: Boots of Superior Divinity | E57: Y

Sheet Chain
A1: Item ID | B1: Glamour | C1: Look of | D1: Flag | E1: Keep
A2: 910642 | B2: Glamour - 'Zaharn's Coronet' | C2: Zaharn's Coronet | E2: Y
A3: 913727 | B3: Glamour - 'Blackened Darksplint Coif' | C3: Blackened Darksplint Coif | E3: Y
A4: 918138 | B4: Glamour - 'Slimy Chain Helm' | C4: Slimy Chain Helm | E4: Y
A5: 917260 | B5: Glamour - 'Hive Poisonmaker's Coif' | C5: Hive Poisonmaker's Coif | E5: Y
A6: 917782 | B6: Glamour - 'Simple Defiant Chain Coif' | C6: Simple Defiant Chain Coif | E6: Y
A7: 933130 | B7: Glamour - 'Deathseeker's Natureward Coif' | C7: Deathseeker's Natureward Coif | E7: Y
A8: 932216 | B8: Glamour - 'Castaway Coif of the Warden' | C8: Castaway Coif of the Warden | E8: Y
A9: 929403 | B9: Glamour - 'Enigmatic Coif of Foresight' | C9: Enigmatic Coif of Foresight | E9: Y
A10: 910644 | B10: Glamour - 'Chainmail Coat' | C10: Chainmail Coat | E10: Y
A11: 913752 | B11: Glamour - 'Blackened Darksplint Tunic' | C11: Blackened Darksplint Tunic | E11: Y
A12: 918139 | B12: Glamour - 'Slimy Chain Breastplate' | C12: Slimy Chain Breastplate | E12: Y
A13: 917268 | B13: Glamour - 'Hive Poisonmaker's Cuirass' | C13: Hive Poisonmaker's Cuirass | E13: Y
... A57: 929402 | B57: Glamour - 'Enigmatic Boots of Foresight' | C57: Enigmatic Boots of Foresight | E57: Y

Sheet Leather
A1: Item ID | B1: Glamour | C1: Look of | D1: Flag | E1: Keep
A2: 910027 | B2: Glamour - 'Mithril Studded Skullcap' | C2: Mithril Studded Skullcap | E2: Y
A3: 913559 | B3: Glamour - 'Black Lace-Boned Skullcap' | C3: Black Lace-Boned Skullcap | E3: Y
A4: 925042 | B4: Glamour - 'Concordant Earthborn Leather Cowl' | C4: Concordant Earthborn Leather Cowl | E4: Y
A5: 924178 | B5: Glamour - 'Druadic Flamehide Cowl' | C5: Druadic Flamehide Cowl | E5: Y
A6: 919567 | B6: Glamour - 'Kizash's Savage Heart Cap' | C6: Kizash's Savage Heart Cap | E6: Y
A7: 927297 | B7: Glamour - 'Flawed Consigned Leather Cap' | C7: Flawed Consigned Leather Cap | E7: Y
A8: 932230 | B8: Glamour - 'Castaway Cowl of the Tender' | C8: Castaway Cowl of the Tender | E8: Y
A9: 912671 | B9: Glamour - 'Sturdy Workmans Cap' | C9: Sturdy Workmans Cap | E9: Y
A10: 910028 | B10: Glamour - 'Mithril Studded Tunic' | C10: Mithril Studded Tunic | E10: Y
A11: 913562 | B11: Glamour - 'Black Lace-Boned Tunic' | C11: Black Lace-Boned Tunic | E11: Y
A12: 910049 | B12: Glamour - 'Mesh Tunic' | C12: Mesh Tunic | E12: Y
A13: 924181 | B13: Glamour - 'Druadic Flamehide Tunic' | C13: Druadic Flamehide Tunic | E13: Y
... A57: 912674 | B57: Glamour - 'Sturdy Workmans Boots' | C57: Sturdy Workmans Boots | E57: Y

Sheet Exotic Helms
A1: Item ID | B1: Glamour | C1: Look of | D1: Flag | E1: Keep
A2: 910063 | B2: Glamour - 'Cured Silk Headband' | C2: Cured Silk Headband | E2: Y
A3: 925161 | B3: Glamour - 'Discordant Windstruck Leather Cowl' | C3: Discordant Windstruck Leather Cowl | E3: Y
A4: 925049 | B4: Glamour - 'Concordant Windstruck Leather Cowl' | C4: Concordant Windstruck Leather Cowl | E4: Y
A5: 928081 | B5: Glamour - 'Iridium Cowl of the Enlightened Anima' | C5: Iridium Cowl of the Enlightened Anima | E5: Y
A6: 924509 | B6: Glamour - 'Purified Stormhide Cowl' | C6: Purified Stormhide Cowl | E6: Y
A7: 933151 | B7: Glamour - 'Deathseeker's Soulforge Cowl' | C7: Deathseeker's Soulforge Cowl | E7: Y
A8: 929722 | B8: Glamour - 'Perspicuous Cowl of Affinity' | C8: Perspicuous Cowl of Affinity | E8: Y
A9: 925833 | B9: Glamour - 'Tainted Windstruck Leather Cowl' | C9: Tainted Windstruck Leather Cowl | E9: Y
A10: 915513 | B10: Glamour - 'Netted Kelp Cap' | C10: Netted Kelp Cap | E10: Y
A11: 915056 | B11: Glamour - 'Shaded Hide skullcap' | C11: Shaded Hide skullcap | E11: Y
A12: 932575 | B12: Glamour - 'Darkwater Lifewalker Cowl' | C12: Darkwater Lifewalker Cowl | E12: Y
A13: 911653 | B13: Glamour - 'Blood Weave Cap' | C13: Blood Weave Cap | E13: Y
... A34: 932582 | B34: Glamour - 'Darkwater Soulforge Cowl' | C34: Darkwater Soulforge Cowl | E34: Y

Sheet Exotic Chests
A1: Item ID | B1: Glamour | C1: Look of | D1: Flag | E1: Keep
A2: 910073 | B2: Glamour - 'Shiverback-hide Jerkin' | C2: Shiverback-hide Jerkin | E2: Y
A3: 925164 | B3: Glamour - 'Discordant Windstruck Leather Tunic' | C3: Discordant Windstruck Leather Tunic | E3: Y
A4: 910064 | B4: Glamour - 'Cured Silk Gi' | C4: Cured Silk Gi | E4: Y
A5: 928084 | B5: Glamour - 'Iridium Chestwraps of the Enlightened Anima' | C5: Iridium Chestwraps of the Enlightened Anima | E5: Y
A6: 924512 | B6: Glamour - 'Purified Stormhide Tunic' | C6: Purified Stormhide Tunic | E6: Y
A7: 933154 | B7: Glamour - 'Deathseeker's Soulforge Tunic' | C7: Deathseeker's Soulforge Tunic | E7: Y
A8: 929725 | B8: Glamour - 'Perspicuous Chestwraps of Affinity' | C8: Perspicuous Chestwraps of Affinity | E8: Y
A9: 925836 | B9: Glamour - 'Tainted Windstruck Leather Tunic' | C9: Tainted Windstruck Leather Tunic | E9: Y
A10: 914257 | B10: Glamour - 'Icicle Tunic' | C10: Icicle Tunic | E10: Y
A11: 915059 | B11: Glamour - 'Shaded Hide Tunic' | C11: Shaded Hide Tunic | E11: Y
A12: 932578 | B12: Glamour - 'Darkwater Lifewalker Tunic' | C12: Darkwater Lifewalker Tunic | E12: Y
A13: 911654 | B13: Glamour - 'Blood Weave Tunic' | C13: Blood Weave Tunic | E13: Y
... A34: 932585 | B34: Glamour - 'Darkwater Soulforge Chestwraps' | C34: Darkwater Soulforge Chestwraps | E34: Y

Sheet Exotic Sleeves
A1: Item ID | B1: Glamour | C1: Look of | D1: Flag | E1: Keep
A2: 910065 | B2: Glamour - 'Cured Silk Sleeves' | C2: Cured Silk Sleeves | E2: Y
A3: 925162 | B3: Glamour - 'Discordant Windstruck Leather Armwraps' | C3: Discordant Windstruck Leather Armwraps | E3: Y
A4: 925050 | B4: Glamour - 'Concordant Windstruck Leather Armwraps' | C4: Concordant Windstruck Leather Armwraps | E4: Y
A5: 928082 | B5: Glamour - 'Iridium Armwraps of the Enlightened Anima' | C5: Iridium Armwraps of the Enlightened Anima | E5: Y
A6: 924510 | B6: Glamour - 'Purified Stormhide Armwraps' | C6: Purified Stormhide Armwraps | E6: Y
A7: 933152 | B7: Glamour - 'Deathseeker's Soulforge Armwraps' | C7: Deathseeker's Soulforge Armwraps | E7: Y
A8: 929723 | B8: Glamour - 'Perspicuous Armwraps of Affinity' | C8: Perspicuous Armwraps of Affinity | E8: Y
A9: 925834 | B9: Glamour - 'Tainted Windstruck Leather Armwraps' | C9: Tainted Windstruck Leather Armwraps | E9: Y
A10: 912166 | B10: Glamour - 'Lined Burlap Sleeves' | C10: Lined Burlap Sleeves | E10: Y
A11: 915053 | B11: Glamour - 'Shaded Hide sleeves' | C11: Shaded Hide sleeves | E11: Y
A12: 932576 | B12: Glamour - 'Darkwater Lifewalker Armwraps' | C12: Darkwater Lifewalker Armwraps | E12: Y
A13: 911655 | B13: Glamour - 'Blood Weave Sleeves' | C13: Blood Weave Sleeves | E13: Y
... A34: 932583 | B34: Glamour - 'Darkwater Soulforge Armwraps' | C34: Darkwater Soulforge Armwraps | E34: Y

Sheet Exotic Bracers
A1: Item ID | B1: Glamour | C1: Look of | D1: Flag | E1: Keep
A2: 910066 | B2: Glamour - 'Cured Silk Wristbands' | C2: Cured Silk Wristbands | E2: Y
A3: 925158 | B3: Glamour - 'Discordant Windstruck Leather Wristguard' | C3: Discordant Windstruck Leather Wristguard | E3: Y
A4: 925046 | B4: Glamour - 'Concordant Windstruck Leather Wristguard' | C4: Concordant Windstruck Leather Wristguard | E4: Y
A5: 928078 | B5: Glamour - 'Iridium Wristguard of the Enlightened Anima' | C5: Iridium Wristguard of the Enlightened Anima | E5: Y
A6: 924506 | B6: Glamour - 'Purified Stormhide Wristguard' | C6: Purified Stormhide Wristguard | E6: Y
A7: 933148 | B7: Glamour - 'Deathseeker's Soulforge Wristguard' | C7: Deathseeker's Soulforge Wristguard | E7: Y
A8: 929719 | B8: Glamour - 'Perspicuous Wristguard of Affinity' | C8: Perspicuous Wristguard of Affinity | E8: Y
A9: 925830 | B9: Glamour - 'Tainted Windstruck Leather Wristguard' | C9: Tainted Windstruck Leather Wristguard | E9: Y
A10: 912011 | B10: Glamour - 'Indigo Snake Bracelet' | C10: Indigo Snake Bracelet | E10: Y
A11: 915058 | B11: Glamour - 'Shaded Hide wristband' | C11: Shaded Hide wristband | E11: Y
A12: 932572 | B12: Glamour - 'Darkwater Lifewalker Wristguard' | C12: Darkwater Lifewalker Wristguard | E12: Y
A13: 911656 | B13: Glamour - 'Blood Weave Bracelet' | C13: Blood Weave Bracelet | E13: Y
... A34: 932579 | B34: Glamour - 'Darkwater Soulforge Wristguard' | C34: Darkwater Soulforge Wristguard | E34: Y

Sheet Exotic Gloves
A1: Item ID | B1: Glamour | C1: Look of | D1: Flag | E1: Keep
A2: 910067 | B2: Glamour - 'Cured Silk Handwraps' | C2: Cured Silk Handwraps | E2: Y
A3: 925159 | B3: Glamour - 'Discordant Windstruck Leather Gloves' | C3: Discordant Windstruck Leather Gloves | E3: Y
A4: 925047 | B4: Glamour - 'Concordant Windstruck Leather Gloves' | C4: Concordant Windstruck Leather Gloves | E4: Y
A5: 928079 | B5: Glamour - 'Iridium Gloves of the Enlightened Anima' | C5: Iridium Gloves of the Enlightened Anima | E5: Y
A6: 924507 | B6: Glamour - 'Purified Stormhide Gloves' | C6: Purified Stormhide Gloves | E6: Y
A7: 933149 | B7: Glamour - 'Deathseeker's Soulforge Gloves' | C7: Deathseeker's Soulforge Gloves | E7: Y
A8: 929720 | B8: Glamour - 'Perspicuous Gloves of Affinity' | C8: Perspicuous Gloves of Affinity | E8: Y
A9: 925831 | B9: Glamour - 'Tainted Windstruck Leather Gloves' | C9: Tainted Windstruck Leather Gloves | E9: Y
A10: 915517 | B10: Glamour - 'Netted Kelp Gloves' | C10: Netted Kelp Gloves | E10: Y
A11: 915055 | B11: Glamour - 'Shaded Hide gloves' | C11: Shaded Hide gloves | E11: Y
A12: 932573 | B12: Glamour - 'Darkwater Lifewalker Gloves' | C12: Darkwater Lifewalker Gloves | E12: Y
A13: 911657 | B13: Glamour - 'Blood Weave Gloves' | C13: Blood Weave Gloves | E13: Y
... A34: 932580 | B34: Glamour - 'Darkwater Soulforge Gloves' | C34: Darkwater Soulforge Gloves | E34: Y

Sheet Exotic Leggings
A1: Item ID | B1: Glamour | C1: Look of | D1: Flag | E1: Keep
A2: 910068 | B2: Glamour - 'Cured Silk Leggings' | C2: Cured Silk Leggings | E2: Y
A3: 925163 | B3: Glamour - 'Discordant Windstruck Leather Leggings' | C3: Discordant Windstruck Leather Leggings | E3: Y
A4: 925051 | B4: Glamour - 'Concordant Windstruck Leather Leggings' | C4: Concordant Windstruck Leather Leggings | E4: Y
A5: 928083 | B5: Glamour - 'Iridium Leggings of the Enlightened Anima' | C5: Iridium Leggings of the Enlightened Anima | E5: Y
A6: 924511 | B6: Glamour - 'Purified Stormhide Leggings' | C6: Purified Stormhide Leggings | E6: Y
A7: 933153 | B7: Glamour - 'Deathseeker's Soulforge Leggings' | C7: Deathseeker's Soulforge Leggings | E7: Y
A8: 929724 | B8: Glamour - 'Perspicuous Leggings of Affinity' | C8: Perspicuous Leggings of Affinity | E8: Y
A9: 925835 | B9: Glamour - 'Tainted Windstruck Leather Leggings' | C9: Tainted Windstruck Leather Leggings | E9: Y
A10: 915518 | B10: Glamour - 'Netted Kelp Pantaloons' | C10: Netted Kelp Pantaloons | E10: Y
A11: 915057 | B11: Glamour - 'Shaded Hide leggings' | C11: Shaded Hide leggings | E11: Y
A12: 932577 | B12: Glamour - 'Darkwater Lifewalker Leggings' | C12: Darkwater Lifewalker Leggings | E12: Y
A13: 911658 | B13: Glamour - 'Blood Weave Pantaloons' | C13: Blood Weave Pantaloons | E13: Y
... A34: 932584 | B34: Glamour - 'Darkwater Soulforge Leggings' | C34: Darkwater Soulforge Leggings | E34: Y

Sheet Exotic Boots
A1: Item ID | B1: Glamour | C1: Look of | D1: Flag | E1: Keep
A2: 910069 | B2: Glamour - 'Cured Silk Sandals' | C2: Cured Silk Sandals | E2: Y
A3: 925160 | B3: Glamour - 'Discordant Windstruck Leather Boots' | C3: Discordant Windstruck Leather Boots | E3: Y
A4: 925048 | B4: Glamour - 'Concordant Windstruck Leather Boots' | C4: Concordant Windstruck Leather Boots | E4: Y
A5: 928080 | B5: Glamour - 'Iridium Boots of the Enlightened Anima' | C5: Iridium Boots of the Enlightened Anima | E5: Y
A6: 924508 | B6: Glamour - 'Purified Stormhide Boots' | C6: Purified Stormhide Boots | E6: Y
A7: 933150 | B7: Glamour - 'Deathseeker's Soulforge Boots' | C7: Deathseeker's Soulforge Boots | E7: Y
A8: 929721 | B8: Glamour - 'Perspicuous Boots of Affinity' | C8: Perspicuous Boots of Affinity | E8: Y
A9: 925832 | B9: Glamour - 'Tainted Windstruck Leather Boots' | C9: Tainted Windstruck Leather Boots | E9: Y
A10: 912517 | B10: Glamour - 'Gooey Boots' | C10: Gooey Boots | E10: Y
A11: 915054 | B11: Glamour - 'Shaded Hide boots' | C11: Shaded Hide boots | E11: Y
A12: 932574 | B12: Glamour - 'Darkwater Lifewalker Boots' | C12: Darkwater Lifewalker Boots | E12: Y
A13: 911659 | B13: Glamour - 'Blood Weave Lined Shoes' | C13: Blood Weave Lined Shoes | E13: Y
... A34: 932581 | B34: Glamour - 'Darkwater Soulforge Boots' | C34: Darkwater Soulforge Boots | E34: Y

Sheet Robes
A1: Item ID | B1: Glamour | C1: Look of | D1: Flag | E1: Keep
A2: 910163 | B2: Glamour - 'Robe of the Elements' | C2: Robe of the Elements | E2: Y
A3: 933186 | B3: Glamour - 'Fabled Crimson Robe of Alendine' | C3: Fabled Crimson Robe of Alendine | E3: Y
A4: 927409 | B4: Glamour - 'Elegant Consigned Silk Robe' | C4: Elegant Consigned Silk Robe | E4: Y
A5: 929053 | B5: Glamour - 'Recondite Soulreaper Robe' | C5: Recondite Soulreaper Robe | E5: Y
A6: 924221 | B6: Glamour - 'Intense Firesilk Robe' | C6: Intense Firesilk Robe | E6: Y
A7: 914953 | B7: Glamour - 'Tserrina's Robe' | C7: Tserrina's Robe | E7: Y
A8: 913885 | B8: Glamour - 'Kelp Robe' | C8: Kelp Robe | E8: Y
A9: 919840 | B9: Glamour - 'Lelyen's Robe of Entrancement' | C9: Lelyen's Robe of Entrancement | E9: Y
A10: 914049 | B10: Glamour - 'Vermilion Robe of Torrefaction' | C10: Vermilion Robe of Torrefaction | E10: Y
A11: 910145 | B11: Glamour - 'Flowing Black Robe' | C11: Flowing Black Robe | E11: Y
A12: 918871 | B12: Glamour - 'Bleak Holiday Robes' | C12: Bleak Holiday Robes | E12: Y
A13: 919248 | B13: Glamour - 'Robe of Wings' | C13: Robe of Wings | E13: Y
... A57: 912340 | B57: Glamour - 'Patched Violet Robe' | C57: Patched Violet Robe | E57: Y

Sheet 1H Slashing
A1: Item ID | B1: Glamour | C1: Look of | D1: Flag | E1: Keep
A2: 9546 | B2: Glamour - 'Sword of Truth' | C2: Sword of Truth | E2: Y
A3: 700091 | B3: Glamour - 'Rusty Shan`Tok' | C3: Rusty Shan`Tok | D3: low-tier word: "rusty" | E3: N
A4: 700093 | B4: Glamour - 'Rusty Fer`Esh' | C4: Rusty Fer`Esh | D4: low-tier word: "rusty" | E4: N
A5: 700095 | B5: Glamour - 'Tainted Teir`Dal Long Sword' | C5: Tainted Teir`Dal Long Sword | E5: Y
A6: 700109 | B6: Glamour - 'Teir`Dal Short Sword' | C6: Teir`Dal Short Sword | E6: Y
A7: 700110 | B7: Glamour - 'Teir`Dal Scimitar' | C7: Teir`Dal Scimitar | E7: Y
A8: 700125 | B8: Glamour - 'Shai`din Life Harvester' | C8: Shai`din Life Harvester | E8: Y
A9: 700197 | B9: Glamour - 'Shadow Flame short sword' | C9: Shadow Flame short sword | E9: Y
A10: 700198 | B10: Glamour - 'Shadow Flame long sword' | C10: Shadow Flame long sword | E10: Y
A11: 700209 | B11: Glamour - 'Vyzh`dra's Render of Souls' | C11: Vyzh`dra's Render of Souls | E11: Y
A12: 700377 | B12: Glamour - 'Forged Deathsteel Pick' | C12: Forged Deathsteel Pick | E12: Y
A13: 700484 | B13: Glamour - 'Sword of Truth, Reforged' | C13: Sword of Truth, Reforged | E13: Y
A14: 700676 | B14: Glamour - 'Claw of Vyzh`dra' | C14: Claw of Vyzh`dra | E14: Y
A15: 700758 | B15: Glamour - 'Elphorn`s Cleaver' | C15: Elphorn`s Cleaver | E15: Y
A16: 700788 | B16: Glamour - 'Jar`Nal Long Sword' | C16: Jar`Nal Long Sword | E16: Y
... A27: 701434 | B27: Glamour - 'Sword of the Mist' | C27: Sword of the Mist | E27: Y
A28: 701467 | B28: Glamour - 'Crude Defiant Axe' | C28: Crude Defiant Axe | D28: low-tier word: "crude" | E28: N
A29: 701480 | B29: Glamour - 'Simple Defiant Bastard Sword' | C29: Simple Defiant Bastard Sword | E29: Y
A30: 701505 | B30: Glamour - 'Ornate Defiant Longsword' | C30: Ornate Defiant Longsword | E30: Y
A31: 701506 | B31: Glamour - 'Ornate Defiant Gladius' | C31: Ornate Defiant Gladius | E31: Y
A32: 701519 | B32: Glamour - 'Flawed Defiant Shortsword' | C32: Flawed Defiant Shortsword | D32: lower Defiant tier | E32: N
A33: 701532 | B33: Glamour - 'Intricate Defiant Scimitar' | C33: Intricate Defiant Scimitar | E33: Y
A34: 701544 | B34: Glamour - 'Elaborate Defiant Kama' | C34: Elaborate Defiant Kama | E34: Y
A35: 701545 | B35: Glamour - 'Elaborate Defiant Cutlass' | C35: Elaborate Defiant Cutlass | E35: Y
A36: 701557 | B36: Glamour - 'Elegant Defiant Shortsword' | C36: Elegant Defiant Shortsword | E36: Y
A37: 701558 | B37: Glamour - 'Elegant Defiant Fireborn Axe' | C37: Elegant Defiant Fireborn Axe | E37: Y
A38: 701727 | B38: Glamour - 'Sword of the Bloodsworn' | C38: Sword of the Bloodsworn | E38: Y
A39: 701817 | B39: Glamour - 'Fabled Polished Granite Tomahawk' | C39: Fabled Polished Granite Tomahawk | E39: Y
A40: 701819 | B40: Glamour - 'Fabled Ghoulbane' | C40: Fabled Ghoulbane | E40: Y
A41: 701871 | B41: Glamour - 'Scimitar of the Relentless' | C41: Scimitar of the Relentless | E41: Y
A42: 701874 | B42: Glamour - 'Gut-Piercing Longsword' | C42: Gut-Piercing Longsword | E42: Y
A43: 701914 | B43: Glamour - 'Bygone Butcher's Cleaver' | C43: Bygone Butcher's Cleaver | E43: Y
A44: 701921 | B44: Glamour - 'Blade of Disruption' | C44: Blade of Disruption | E44: Y
... A186: 705364 | B186: Glamour - 'Dreamshadow Blade' | C186: Dreamshadow Blade | E186: Y
A187: 705393 | B187: Glamour - 'Steel Seed Blade' | C187: Steel Seed Blade | D187: basic metal: steel | E187: N
A188: 705394 | B188: Glamour - 'Sword of an Unknown Victim' | C188: Sword of an Unknown Victim | E188: Y
A189: 705395 | B189: Glamour - 'Husk Sharpened Axe' | C189: Husk Sharpened Axe | E189: Y
A190: 705428 | B190: Glamour - 'Vermin Slicer' | C190: Vermin Slicer | E190: Y
A191: 705429 | B191: Glamour - 'Sea Ranger's Blade' | C191: Sea Ranger's Blade | E191: Y
...

Sheet 1H Blunt
A1: Item ID | B1: Glamour | C1: Look of | D1: Flag | E1: Keep
A2: 700066 | B2: Glamour - 'Scepter of Al`Kabor' | C2: Scepter of Al`Kabor | E2: Y
A3: 700118 | B3: Glamour - 'Di`zok Oracle Shillelagh' | C3: Di`zok Oracle Shillelagh | E3: Y
A4: 700120 | B4: Glamour - 'Guard Captain`s Mallet' | C4: Guard Captain`s Mallet | E4: Y
A5: 700121 | B5: Glamour - 'Di`zok Sceptre of Authority' | C5: Di`zok Sceptre of Authority | E5: Y
A6: 700122 | B6: Glamour - 'Writ of Di`zok' | C6: Writ of Di`zok | E6: Y
A7: 700131 | B7: Glamour - 'Di`zok Escape Staff' | C7: Di`zok Escape Staff | E7: Y
A8: 700134 | B8: Glamour - 'Teir`Dal Warhammer' | C8: Teir`Dal Warhammer | E8: Y
A9: 700136 | B9: Glamour - 'Teir`Dal Morning Star' | C9: Teir`Dal Morning Star | E9: Y
A10: 700199 | B10: Glamour - 'Shadow Flame mace' | C10: Shadow Flame mace | E10: Y
A11: 700200 | B11: Glamour - 'Shadow Flame staff' | C11: Shadow Flame staff | E11: Y
A12: 700488 | B12: Glamour - 'Fist of Innoruuk' | C12: Fist of Innoruuk | E12: Y
A13: 700581 | B13: Glamour - 'Shissar Elementalist`s Cane' | C13: Shissar Elementalist`s Cane | E13: Y
... A26: 701418 | B26: Glamour - 'Fabled Blackstar, Mace of Night' | C26: Fabled Blackstar, Mace of Night | E26: Y
A27: 701464 | B27: Glamour - 'Crude Defiant Mace' | C27: Crude Defiant Mace | D27: lower Defiant tier | E27: N
A28: 701465 | B28: Glamour - 'Crude Defiant Club' | C28: Crude Defiant Club | D28: low-tier word: "crude" | E28: N
A29: 701477 | B29: Glamour - 'Simple Defiant Hammer' | C29: Simple Defiant Hammer | D29: lower Defiant tier | E29: N
A30: 701478 | B30: Glamour - 'Simple Defiant Wand' | C30: Simple Defiant Wand | E30: Y
A31: 701490 | B31: Glamour - 'Rough Defiant Hammer' | C31: Rough Defiant Hammer | D31: lower Defiant tier | E31: N
A32: 701503 | B32: Glamour - 'Ornate Defiant Bone Sledgehammer' | C32: Ornate Defiant Bone Sledgehammer | E32: Y
A33: 701504 | B33: Glamour - 'Ornate Defiant Scepter' | C33: Ornate Defiant Scepter | E33: Y
A34: 701516 | B34: Glamour - 'Flawed Defiant Brawl Stick' | C34: Flawed Defiant Brawl Stick | D34: low-tier word: "flawed" | E34: N
A35: 701529 | B35: Glamour - 'Intricate Defiant Hammer' | C35: Intricate Defiant Hammer | E35: Y
A36: 701530 | B36: Glamour - 'Intricate Defiant Mace' | C36: Intricate Defiant Mace | E36: Y
A37: 701542 | B37: Glamour - 'Elaborate Defiant Spikemaul' | C37: Elaborate Defiant Spikemaul | E37: Y
A38: 701543 | B38: Glamour - 'Elaborate Defiant Dragonrod' | C38: Elaborate Defiant Dragonrod | E38: Y
A39: 701555 | B39: Glamour - 'Elegant Defiant Square Hammer' | C39: Elegant Defiant Square Hammer | E39: Y
A40: 701556 | B40: Glamour - 'Elegant Defiant Sceptre' | C40: Elegant Defiant Sceptre | E40: Y
A41: 701712 | B41: Glamour - 'Ancient Crude Club' | C41: Ancient Crude Club | D41: low-tier word: "crude" | E41: N
A42: 701725 | B42: Glamour - 'Copper Hammer of Striking' | C42: Copper Hammer of Striking | E42: Y
A43: 701826 | B43: Glamour - 'Fabled Slime Crystal Staff' | C43: Fabled Slime Crystal Staff | E43: Y
A44: 701829 | B44: Glamour - 'Fabled Staff of Writhing' | C44: Fabled Staff of Writhing | E44: Y
A45: 701922 | B45: Glamour - 'Mace of Memories' | C45: Mace of Memories | E45: Y
A46: 701929 | B46: Glamour - 'Coldforged War Hammer' | C46: Coldforged War Hammer | E46: Y
A47: 701930 | B47: Glamour - 'Wand of Wintergrip' | C47: Wand of Wintergrip | E47: Y
A48: 701942 | B48: Glamour - 'Frostcaller' | C48: Frostcaller | E48: Y
A49: 701954 | B49: Glamour - 'Burnished Mace of Tenacity' | C49: Burnished Mace of Tenacity | E49: Y
A50: 701969 | B50: Glamour - 'Torkin's Club of Pain' | C50: Torkin's Club of Pain | E50: Y
A51: 701970 | B51: Glamour - 'Shiny Hammer of Chaos' | C51: Shiny Hammer of Chaos | E51: Y
A52: 702003 | B52: Glamour - 'Despair' | C52: Despair | E52: Y
...

Sheet 1H Piercing
A1: Item ID | B1: Glamour | C1: Look of | D1: Flag | E1: Keep
A2: 700100 | B2: Glamour - 'Enchanted Teir`Dal Rapier' | C2: Enchanted Teir`Dal Rapier | E2: Y
A3: 700127 | B3: Glamour - 'Sarnak Summoner`s Dagger' | C3: Sarnak Summoner`s Dagger | E3: Y
A4: 700177 | B4: Glamour - 'Teir`Dal Dagger' | C4: Teir`Dal Dagger | E4: Y
A5: 700178 | B5: Glamour - 'Teir`Dal Spear' | C5: Teir`Dal Spear | E5: Y
A6: 700201 | B6: Glamour - 'Shadow Flame dagger' | C6: Shadow Flame dagger | E6: Y
A7: 700489 | B7: Glamour - 'Crystal Shiv of Nightmares' | C7: Crystal Shiv of Nightmares | E7: Y
A8: 700608 | B8: Glamour - 'Ry`Gorr Mining Pick' | C8: Ry`Gorr Mining Pick | E8: Y
A9: 700757 | B9: Glamour - 'Rei`s Battleworn Dirk' | C9: Rei`s Battleworn Dirk | E9: Y
A10: 700929 | B10: Glamour - 'Fabled Gore Covered Horn' | C10: Fabled Gore Covered Horn | E10: Y
A11: 700979 | B11: Glamour - 'Fabled Akhevan Shadow Shears' | C11: Fabled Akhevan Shadow Shears | E11: Y
A12: 701256 | B12: Glamour - 'Fabled Coral Hilted Shortsword' | C12: Fabled Coral Hilted Shortsword | E12: Y
A13: 701265 | B13: Glamour - 'Fabled Sharp Gem Formation' | C13: Fabled Sharp Gem Formation | E13: Y
... A17: 701400 | B17: Glamour - 'Fabled Horn of Hsagra' | C17: Fabled Horn of Hsagra | E17: Y
A18: 701468 | B18: Glamour - 'Crude Defiant Dagger' | C18: Crude Defiant Dagger | D18: lower Defiant tier | E18: N
A19: 701481 | B19: Glamour - 'Simple Defiant Claw-dagger' | C19: Simple Defiant Claw-dagger | E19: Y
A20: 701495 | B20: Glamour - 'Rough Defiant Serrated Dagger' | C20: Rough Defiant Serrated Dagger | D20: low-tier word: "rough" | E20: N
A21: 701508 | B21: Glamour - 'Ornate Defiant Dagger' | C21: Ornate Defiant Dagger | E21: Y
A22: 701520 | B22: Glamour - 'Flawed Defiant Glass Shard' | C22: Flawed Defiant Glass Shard | D22: low-tier word: "flawed" | E22: N
A23: 701521 | B23: Glamour - 'Flawed Defiant Dagger' | C23: Flawed Defiant Dagger | D23: lower Defiant tier | E23: N
A24: 701533 | B24: Glamour - 'Intricate Defiant Sacrificial Dagger' | C24: Intricate Defiant Sacrificial Dagger | E24: Y
A25: 701534 | B25: Glamour - 'Intricate Defiant Partisan Spear' | C25: Intricate Defiant Partisan Spear | E25: Y
A26: 701546 | B26: Glamour - 'Elaborate Defiant Rapier' | C26: Elaborate Defiant Rapier | E26: Y
A27: 701547 | B27: Glamour - 'Elaborate Defiant Flint Spear' | C27: Elaborate Defiant Flint Spear | E27: Y
A28: 701559 | B28: Glamour - 'Elegant Defiant Nightblade' | C28: Elegant Defiant Nightblade | E28: Y
A29: 701560 | B29: Glamour - 'Elegant Defiant Dayblade' | C29: Elegant Defiant Dayblade | E29: Y
A30: 701673 | B30: Glamour - 'Yar`Lir's Fang' | C30: Yar`Lir's Fang | E30: Y
A31: 701707 | B31: Glamour - 'Trident of Freed Spirits' | C31: Trident of Freed Spirits | E31: Y
A32: 701917 | B32: Glamour - 'Soulpiercer' | C32: Soulpiercer | E32: Y
A33: 701938 | B33: Glamour - 'Trident of the Pyrilen' | C33: Trident of the Pyrilen | E33: Y
A34: 701982 | B34: Glamour - 'Dagger of Dawn' | C34: Dagger of Dawn | E34: Y
A35: 701997 | B35: Glamour - 'Murkchitin Shard' | C35: Murkchitin Shard | E35: Y
... A39: 702138 | B39: Glamour - 'Dragontooth Shard' | C39: Dragontooth Shard | E39: Y
A40: 702158 | B40: Glamour - 'Broken Mandible of the Broodqueen' | C40: Broken Mandible of the Broodqueen | D40: low-tier word: "broken" | E40: N
A41: 702185 | B41: Glamour - 'Fang of Kessdona' | C41: Fang of Kessdona | E41: Y
A42: 702215 | B42: Glamour - 'Mace of the Fallen Hero' | C42: Mace of the Fallen Hero | E42: Y
A43: 702275 | B43: Glamour - 'Flame Etched Dagger' | C43: Flame Etched Dagger | E43: Y
A44: 702280 | B44: Glamour - 'Ellyra's Dagger of Revenge' | C44: Ellyra's Dagger of Revenge | E44: Y
A45: 702296 | B45: Glamour - 'Fabled Wicked Shank' | C45: Fabled Wicked Shank | E45: Y
A46: 702298 | B46: Glamour - 'Fabled Bejeweled Dagger of Summoning' | C46: Fabled Bejeweled Dagger of Summoning | E46: Y
...

Sheet Two-Handed
A1: Item ID | B1: Glamour | C1: Look of | D1: Flag | E1: Keep
A2: 700098 | B2: Glamour - 'Enchanted Teir`Dal Bastard Sword' | C2: Enchanted Teir`Dal Bastard Sword | E2: Y
A3: 700099 | B3: Glamour - 'Enchanted Teir`Dal Great Staff' | C3: Enchanted Teir`Dal Great Staff | E3: Y
A4: 700108 | B4: Glamour - 'Teir`Dal Two Handed Sword' | C4: Teir`Dal Two Handed Sword | E4: Y
A5: 700116 | B5: Glamour - 'Worn Shai`din Naginata' | C5: Worn Shai`din Naginata | D5: low-tier word: "worn" | E5: N
A6: 700196 | B6: Glamour - 'Lunar maul' | C6: Lunar maul | E6: Y
A7: 700203 | B7: Glamour - 'Shadow Flame Lance' | C7: Shadow Flame Lance | E7: Y
A8: 700204 | B8: Glamour - 'Shadow Flame Warsword' | C8: Shadow Flame Warsword | E8: Y
A9: 700376 | B9: Glamour - 'Barbarian Spiritist`s Hammer' | C9: Barbarian Spiritist`s Hammer | E9: Y
A10: 700485 | B10: Glamour - 'Blazing Staff of Solusek Ro' | C10: Blazing Staff of Solusek Ro | E10: Y
A11: 700490 | B11: Glamour - 'Greataxe of the Warlord' | C11: Greataxe of the Warlord | E11: Y
A12: 700759 | B12: Glamour - 'Norge`tal' | C12: Norge`tal | E12: Y
A13: 700778 | B13: Glamour - 'Dyn`leth Steel 2h Sword' | C13: Dyn`leth Steel 2h Sword | E13: Y
A14: 701017 | B14: Glamour - 'Fabled Cudgel of Cowardly Death' | C14: Fabled Cudgel of Cowardly Death | E14: Y
A15: 701216 | B15: Glamour - 'Fabled Diaku Forged War Hammer' | C15: Fabled Diaku Forged War Hammer | E15: Y
A16: 701250 | B16: Glamour - 'Fabled Spear of Fire' | C16: Fabled Spear of Fire | E16: Y
A17: 701255 | B17: Glamour - 'Fabled Coral Hilted Tulwar' | C17: Fabled Coral Hilted Tulwar | E17: Y
... A25: 701427 | B25: Glamour - 'Fabled Tantor's Tusk' | C25: Fabled Tantor's Tusk | E25: Y
A26: 701472 | B26: Glamour - 'Crude Defiant Greatspear' | C26: Crude Defiant Greatspear | D26: low-tier word: "crude" | E26: N
A27: 701484 | B27: Glamour - 'Simple Defiant Twisted Staff' | C27: Simple Defiant Twisted Staff | E27: Y
A28: 701485 | B28: Glamour - 'Simple Defiant Spear' | C28: Simple Defiant Spear | E28: Y
A29: 701486 | B29: Glamour - 'Simple Defiant Greataxe' | C29: Simple Defiant Greataxe | E29: Y
A30: 701497 | B30: Glamour - 'Rough Defiant Spiked Staff' | C30: Rough Defiant Spiked Staff | D30: low-tier word: "rough" | E30: N
A31: 701498 | B31: Glamour - 'Rough Defiant Trident' | C31: Rough Defiant Trident | D31: lower Defiant tier | E31: N
A32: 701499 | B32: Glamour - 'Rough Defiant Halberd' | C32: Rough Defiant Halberd | D32: low-tier word: "rough" | E32: N
A33: 701511 | B33: Glamour - 'Ornate Defiant Harpoon' | C33: Ornate Defiant Harpoon | E33: Y
A34: 701512 | B34: Glamour - 'Ornate Defiant Scythe' | C34: Ornate Defiant Scythe | E34: Y
A35: 701523 | B35: Glamour - 'Flawed Defiant Quarterstaff' | C35: Flawed Defiant Quarterstaff | D35: low-tier word: "flawed" | E35: N
A36: 701525 | B36: Glamour - 'Flawed Defiant Emeraldblade' | C36: Flawed Defiant Emeraldblade | D36: low-tier word: "flawed" | E36: N
A37: 701536 | B37: Glamour - 'Intricate Defiant Spiked Warhammer' | C37: Intricate Defiant Spiked Warhammer | E37: Y
A38: 701537 | B38: Glamour - 'Intricate Defiant Trident' | C38: Intricate Defiant Trident | E38: Y
A39: 701538 | B39: Glamour - 'Intricate Defiant Greatsword' | C39: Intricate Defiant Greatsword | E39: Y
A40: 701549 | B40: Glamour - 'Elaborate Defiant Minotaur Staff' | C40: Elaborate Defiant Minotaur Staff | E40: Y
A41: 701550 | B41: Glamour - 'Elaborate Defiant Poleaxe' | C41: Elaborate Defiant Poleaxe | E41: Y
A42: 701551 | B42: Glamour - 'Elaborate Defiant Claymore' | C42: Elaborate Defiant Claymore | E42: Y
A43: 701562 | B43: Glamour - 'Elegant Defiant Warhammer' | C43: Elegant Defiant Warhammer | E43: Y
A44: 701563 | B44: Glamour - 'Elegant Defiant Forked Spear' | C44: Elegant Defiant Forked Spear | E44: Y
A45: 701564 | B45: Glamour - 'Elegant Defiant Battleaxe' | C45: Elegant Defiant Battleaxe | E45: Y
A46: 701709 | B46: Glamour - 'Great Axe of Decapitation' | C46: Great Axe of Decapitation | E46: Y
A47: 701713 | B47: Glamour - 'Mystical Staff of Prosperity' | C47: Mystical Staff of Prosperity | E47: Y
...

Sheet Shields
A1: Item ID | B1: Glamour | C1: Look of | D1: Flag | E1: Keep
A2: 700063 | B2: Glamour - 'Hollowed Koada`Dal Rib Cage' | C2: Hollowed Koada`Dal Rib Cage | E2: Y
A3: 700124 | B3: Glamour - 'History of the Di`zok' | C3: History of the Di`zok | E3: Y
A4: 700487 | B4: Glamour - 'Shining Shield of Marr' | C4: Shining Shield of Marr | E4: Y
A5: 700559 | B5: Glamour - 'Koada`Dal Woodlanders Shield' | C5: Koada`Dal Woodlanders Shield | E5: Y
A6: 700828 | B6: Glamour - 'Ry`Gorr Oracle Shield' | C6: Ry`Gorr Oracle Shield | E6: Y
A7: 700887 | B7: Glamour - 'Recherche` Orb of Aknanook' | C7: Recherche` Orb of Aknanook | E7: Y
A8: 700987 | B8: Glamour - 'Fabled Shield of Mental Fortitude' | C8: Fabled Shield of Mental Fortitude | E8: Y
A9: 700988 | B9: Glamour - 'Fabled Shield of the Creator' | C9: Fabled Shield of the Creator | E9: Y
A10: 700999 | B10: Glamour - 'Fabled Aegis of Judgment' | C10: Fabled Aegis of Judgment | E10: Y
A11: 701029 | B11: Glamour - 'Fabled Scepter of Calekor' | C11: Fabled Scepter of Calekor | E11: Y
A12: 701039 | B12: Glamour - 'Fabled Insanity Crawler hide shield' | C12: Fabled Insanity Crawler hide shield | E12: Y
A13: 701247 | B13: Glamour - 'Torklar`s Battered Shield' | C13: Torklar`s Battered Shield | E13: Y
... A20: 701489 | B20: Glamour - 'Simple Defiant Wooden Shield' | C20: Simple Defiant Wooden Shield | E20: Y
A21: 701501 | B21: Glamour - 'Rough Defiant Chitin Shield' | C21: Rough Defiant Chitin Shield | D21: low-tier word: "rough" | E21: N
A22: 701502 | B22: Glamour - 'Rough Defiant Round Shield' | C22: Rough Defiant Round Shield | D22: lower Defiant tier | E22: N
A23: 701540 | B23: Glamour - 'Intricate Defiant Hammered Buckler' | C23: Intricate Defiant Hammered Buckler | E23: Y
A24: 701553 | B24: Glamour - 'Elaborate Defiant Aegis' | C24: Elaborate Defiant Aegis | E24: Y
A25: 701554 | B25: Glamour - 'Elaborate Defiant Heater' | C25: Elaborate Defiant Heater | E25: Y
A26: 701566 | B26: Glamour - 'Elegant Defiant Round Shield' | C26: Elegant Defiant Round Shield | E26: Y
A27: 701567 | B27: Glamour - 'Elegant Defiant Buckler' | C27: Elegant Defiant Buckler | E27: Y
A28: 701880 | B28: Glamour - 'Shield of Frightfulness' | C28: Shield of Frightfulness | E28: Y
A29: 701893 | B29: Glamour - 'Shield of the Maniacal' | C29: Shield of the Maniacal | E29: Y
A30: 701944 | B30: Glamour - 'Shield of Twisted Reality' | C30: Shield of Twisted Reality | E30: Y
A31: 701989 | B31: Glamour - 'Slaver's Buckler of Station' | C31: Slaver's Buckler of Station | E31: Y
A32: 701999 | B32: Glamour - 'Crysnos, Shield of the Rift' | C32: Crysnos, Shield of the Rift | E32: Y
A33: 702006 | B33: Glamour - 'Bane of the Stonegazer' | C33: Bane of the Stonegazer | E33: Y
A34: 702072 | B34: Glamour - 'Razor-Edged Shield of War' | C34: Razor-Edged Shield of War | E34: Y
... A169: 705917 | B169: Glamour - 'Barrier of Flowing Light' | C169: Barrier of Flowing Light | E169: Y
A170: 705918 | B170: Glamour - 'Prototype SH32' | C170: Prototype SH32 | D170: test/placeholder | E170: N
A171: 705957 | B171: Glamour - 'Verdant Shield of the Shissar' | C171: Verdant Shield of the Shissar | E171: Y
A172: 705958 | B172: Glamour - 'Umbralforge Shield' | C172: Umbralforge Shield | E172: Y
A173: 706030 | B173: Glamour - 'Darkwater Buckler' | C173: Darkwater Buckler | E173: Y
A174: 706101 | B174: Glamour - 'Guard of the Blood Raven' | C174: Guard of the Blood Raven | E174: Y
A175: 706168 | B175: Glamour - 'Obexa Animus' | C175: Obexa Animus | E175: Y
A176: 706210 | B176: Glamour - 'Writhing Rubbery Shield' | C176: Writhing Rubbery Shield | E176: Y
A177: 901023 | B177: Glamour - 'Marr's Promise' | C177: Marr's Promise | E177: Y
A178: 901025 | B178: Glamour - 'Envy' | C178: Envy | E178: Y
A179: 901186 | B179: Glamour - 'Buckler of the Recruit' | C179: Buckler of the Recruit | E179: Y
A180: 901188 | B180: Glamour - 'Buckler of the Beetle' | C180: Buckler of the Beetle | E180: Y
...

Sheet Fist & Ranged
A1: Item ID | B1: Glamour | C1: Look of | D1: Flag | E1: Keep
A2: 700205 | B2: Glamour - 'Shadow Flame Claws' | C2: Shadow Flame Claws | E2: Y
A3: 700206 | B3: Glamour - 'Shadow Flame Handwraps' | C3: Shadow Flame Handwraps | E3: Y
A4: 700486 | B4: Glamour - 'Celestial Bow of Karana' | C4: Celestial Bow of Karana | E4: Y
A5: 700681 | B5: Glamour - 'Fangs of Vyzh`dra' | C5: Fangs of Vyzh`dra | E5: Y
A6: 701037 | B6: Glamour - 'Fabled Bow of Storms' | C6: Fabled Bow of Storms | E6: Y
A7: 701252 | B7: Glamour - 'Fabled Savage Platinum Fists' | C7: Fabled Savage Platinum Fists | E7: Y
A8: 701253 | B8: Glamour - 'Fabled Earthen Fist' | C8: Fabled Earthen Fist | E8: Y
A9: 701437 | B9: Glamour - 'Vae`Aender, Stitch's Bow' | C9: Vae`Aender, Stitch's Bow | E9: Y
A10: 701474 | B10: Glamour - 'Crude Defiant Bow' | C10: Crude Defiant Bow | D10: lower Defiant tier | E10: N
A11: 701483 | B11: Glamour - 'Simple Defiant Ulak' | C11: Simple Defiant Ulak | E11: Y
A12: 701500 | B12: Glamour - 'Rough Defiant Bow' | C12: Rough Defiant Bow | D12: lower Defiant tier | E12: N
A13: 701513 | B13: Glamour - 'Ornate Defiant Bow' | C13: Ornate Defiant Bow | E13: Y
A14: 701522 | B14: Glamour - 'Flawed Defiant Orb' | C14: Flawed Defiant Orb | D14: low-tier word: "flawed" | E14: N
A15: 701526 | B15: Glamour - 'Flawed Defiant Longbow' | C15: Flawed Defiant Longbow | D15: low-tier word: "flawed" | E15: N
A16: 701535 | B16: Glamour - 'Intricate Defiant Handwraps' | C16: Intricate Defiant Handwraps | E16: Y
A17: 701548 | B17: Glamour - 'Elaborate Defiant Quickclaw' | C17: Elaborate Defiant Quickclaw | E17: Y
A18: 701552 | B18: Glamour - 'Elaborate Defiant Recurve Bow' | C18: Elaborate Defiant Recurve Bow | E18: Y
A19: 701561 | B19: Glamour - 'Elegant Defiant Knuckle Guards' | C19: Elegant Defiant Knuckle Guards | E19: Y
A20: 702022 | B20: Glamour - 'Zun`Muram Katar' | C20: Zun`Muram Katar | E20: Y
A21: 702057 | B21: Glamour - 'Crystal Hilted Shinai' | C21: Crystal Hilted Shinai | E21: Y
A22: 702377 | B22: Glamour - 'Fabled Battle Fists' | C22: Fabled Battle Fists | E22: Y
A23: 702427 | B23: Glamour - 'Jonas Dagmire's Right Hook' | C23: Jonas Dagmire's Right Hook | E23: Y
A24: 702479 | B24: Glamour - 'Sharpened Talons of the Lycanthrope' | C24: Sharpened Talons of the Lycanthrope | E24: Y
A25: 702496 | B25: Glamour - 'Ball of Sunlight' | C25: Ball of Sunlight | E25: Y
A26: 702523 | B26: Glamour - 'Syncall's Soul' | C26: Syncall's Soul | E26: Y
A27: 702812 | B27: Glamour - 'Cryptwood Tonfa' | C27: Cryptwood Tonfa | E27: Y
... A69: 705278 | B69: Glamour - 'Mesmerizing Ripper' | C69: Mesmerizing Ripper | E69: Y
A70: 705279 | B70: Glamour - 'Warped Chitin Bow' | C70: Warped Chitin Bow | D70: low-tier word: "warped" | E70: N
A71: 705296 | B71: Glamour - 'Dreadiron Knuckles' | C71: Dreadiron Knuckles | E71: Y
A72: 705319 | B72: Glamour - 'Arcane Library Paperweight' | C72: Arcane Library Paperweight | E72: Y
A73: 705320 | B73: Glamour - 'Luminous Dreampiercer' | C73: Luminous Dreampiercer | E73: Y
A74: 705347 | B74: Glamour - 'Preener's Kidgloves' | C74: Preener's Kidgloves | E74: Y
A75: 705348 | B75: Glamour - 'Scalebone, Memoire of Tynn' | C75: Scalebone, Memoire of Tynn | E75: Y
A76: 705349 | B76: Glamour - 'Mindstain Bow of Onerous Accuracy' | C76: Mindstain Bow of Onerous Accuracy | E76: Y
A77: 705379 | B77: Glamour - 'Maleg's Claws' | C77: Maleg's Claws | E77: Y
A78: 705380 | B78: Glamour - 'Sleeper's Embrace' | C78: Sleeper's Embrace | E78: Y
A79: 705381 | B79: Glamour - 'Lenquelle's Longbow' | C79: Lenquelle's Longbow | E79: Y
A80: 705410 | B80: Glamour - 'Claws of the Bane' | C80: Claws of the Bane | E80: Y
A81: 705411 | B81: Glamour - 'Spiked Rage' | C81: Spiked Rage | E81: Y
...

Sheet Unusual Weapons
A1: Item ID | B1: Glamour | C1: Look of | D1: Flag | E1: Keep
A2: 2828 | B2: Glamour - 'Frostrime Kopesh' | C2: Frostrime Kopesh | E2: Y
A3: 2829 | B3: Glamour - 'Frostrime Hammer' | C3: Frostrime Hammer | E3: Y
A4: 2830 | B4: Glamour - 'Frostrime Naginata' | C4: Frostrime Naginata | E4: Y
A5: 2854 | B5: Glamour - 'Frostrime Staff' | C5: Frostrime Staff | E5: Y
A6: 2855 | B6: Glamour - 'Frostrime Bow' | C6: Frostrime Bow | E6: Y
A7: 2856 | B7: Glamour - 'Frostrime Cestus' | C7: Frostrime Cestus | E7: Y
A8: 2857 | B8: Glamour - 'Frostrime Shield' | C8: Frostrime Shield | E8: Y
A9: 4038 | B9: Glamour - 'Frostrime Dagger' | C9: Frostrime Dagger | E9: Y
A10: 17656 | B10: Glamour - 'Staff of Baneful Rituals' | C10: Staff of Baneful Rituals | E10: Y
A11: 17657 | B11: Glamour - 'Scythe of Baneful Rituals' | C11: Scythe of Baneful Rituals | E11: Y
A12: 17658 | B12: Glamour - 'Blade of Baneful Rituals' | C12: Blade of Baneful Rituals | E12: Y
A13: 17659 | B13: Glamour - 'Dagger of Baneful Rituals' | C13: Dagger of Baneful Rituals | E13: Y
... A22: 17669 | B22: Glamour - 'I'd Crit You' | C22: I'd Crit You | E22: Y
A23: 17670 | B23: Glamour - 'No Rez 4 U' | C23: No Rez 4 U | D23: joke name | E23: N
A24: 17671 | B24: Glamour - 'Love is Weak' | C24: Love is Weak | E24: Y
A25: 17672 | B25: Glamour - 'Ur Pet's Hotter' | C25: Ur Pet's Hotter | D25: joke name | E25: N
A26: 17673 | B26: Glamour - 'U Got Trolled' | C26: U Got Trolled | D26: joke name | E26: N
A27: 17674 | B27: Glamour - 'I H8 U' | C27: I H8 U | D27: joke name | E27: N
A28: 17675 | B28: Glamour - 'I H8 This Day' | C28: I H8 This Day | D28: joke name | E28: N
A29: 17676 | B29: Glamour - 'Bite Me' | C29: Bite Me | E29: Y
A30: 17677 | B30: Glamour - 'My Erollisi' | C30: My Erollisi | E30: Y
A31: 17678 | B31: Glamour - 'Ur Epic!' | C31: Ur Epic! | D31: joke name | E31: N
A32: 17679 | B32: Glamour - 'Raid with Me' | C32: Raid with Me | E32: Y
A33: 17680 | B33: Glamour - 'U Mezz Me' | C33: U Mezz Me | D33: joke name | E33: N
A34: 17681 | B34: Glamour - 'U Slay My <3' | C34: U Slay My <3 | D34: joke name | E34: N
A35: 17682 | B35: Glamour - 'Neck Romancer' | C35: Neck Romancer | E35: Y
A36: 17683 | B36: Glamour - 'Lay on Hands' | C36: Lay on Hands | E36: Y
A37: 17684 | B37: Glamour - 'Heart Protector's Blade' | C37: Heart Protector's Blade | E37: Y
A38: 17685 | B38: Glamour - 'Heart Protector's Hammer' | C38: Heart Protector's Hammer | E38: Y
A39: 17686 | B39: Glamour - 'Heart Protector's Greatmace' | C39: Heart Protector's Greatmace | E39: Y
A40: 17687 | B40: Glamour - 'Heart Protector's Shortsword' | C40: Heart Protector's Shortsword | E40: Y
A41: 17688 | B41: Glamour - 'Heart Protector's Dagger' | C41: Heart Protector's Dagger | E41: Y
A42: 17712 | B42: Glamour - 'Heart Protector's Spear' | C42: Heart Protector's Spear | E42: Y
A43: 17713 | B43: Glamour - 'Ornate Heartguard Hammer' | C43: Ornate Heartguard Hammer | E43: Y
A44: 17714 | B44: Glamour - 'Ornate Heartguard Staff' | C44: Ornate Heartguard Staff | E44: Y
A45: 17715 | B45: Glamour - 'Ornate Heartguard Shortsword' | C45: Ornate Heartguard Shortsword | E45: Y
A46: 17716 | B46: Glamour - 'Ornate Heartguard Greatblade' | C46: Ornate Heartguard Greatblade | E46: Y
... A76: 700060 | B76: Glamour - 'Starmetal Ore' | C76: Starmetal Ore | E76: Y
A77: 700061 | B77: Glamour - 'Tome of Unseen Darkness' | C77: Tome of Unseen Darkness | D77: not gear | E77: N
...
